34219102 R vng 100
34219102 R wng 100
34219102 A cog B 44.15 100
34219103 A dog B 44.15 100
34219104 A eog B 44.08 100
34219104 A fog S 44.20 200
34219104 R lng 100
34219104 A gog S 44.19 250
34219105 R xng 100
34219109 R zng 100
34219110 A hog S 44.18 100
34219110 R bog 200
34219111 A iog S 44.19 200
34219112 R gng 100
34219114 A jog S 44.18 100
34219115 R hog 100
34219116 A kog S 44.18 100
34219116 R iog 200
34219117 A log S 44.19 200
34219122 R jog 100
34219130 A mog S 44.18 100
34219135 A nog B 44.08 100
34219135 R eog 100
34219137 R zmg 250
34219138 R kog 100
34219138 A oog B 44.13 250
34219139 A pog S 44.18 100
34219141 R aog 200
34219141 A qog B 44.13 200
34219142 A rog S 44.25 100
34219142 R rog 100
34219142 A sog S 44.18 100
34219142 A tog S 44.18 100
34219150 R mog 100
34219156 R tog 100
34219160 R sog 100
34219160 A uog S 44.18 100
34219161 A vog S 44.18 100
34219161 R gog 250
34219162 A wog S 44.18 250
34219166 A xog B 44.08 100
34219166 R nog 100
34219168 R pog 100
34219169 R wog 250
34219169 A yog S 44.18 100
34219169 R log 200
34219170 A zog S 44.19 200
34219171 A apg S 44.18 100
34219171 A bpg S 44.19 250
34219172 A cpg S 44.25 100
34219173 A dpg S 44.25 100
34219174 R cpg 100
34219174 R zog 200
34219178 A epg S 44.19 200
34219184 R qng 100
34219196 A fpg B 44.15 100
34219197 A gpg B 44.08 100
34219197 R xog 100
34219205 A hpg S 44.25 100
34219205 R dpg 100
34219224 R epg 200
34219225 R dog 100
34219225 R cog 100
34219225 A ipg B 44.15 100
34219225 A jpg B 44.15 100
34219227 A kpg B 44.09 100
34219228 R gpg 100
34219270 A lpg S 44.19 200
34219278 R yog 100
34219279 A mpg S 44.18 100
34219279 R bpg 250
34219280 A npg S 44.18 250
34219281 R lpg 200
34219281 A opg S 44.18 200
34219282 A ppg S 44.17 100
34219286 A qpg S 44.17 100
34219289 R vog 100
34219290 R oog 250
34219293 A rpg B 44.12 250
34219298 R mpg 100
34219299 A spg S 44.17 100
34219300 R spg 100
34219300 A tpg B 44.09 100
34219300 R kpg 100
34219300 R rpg 250
34219300 A upg S 44.18 100
34219300 R ppg 100
34219302 A vpg B 44.12 250
34219308 R vpg 250
34219308 A wpg B 44.12 250
34219308 A xpg S 44.23 100
34219309 R hpg 100
34219319 R wpg 250
34219321 A ypg B 44.12 250
34219322 R upg 100
34219322 R opg 200
34219322 R ypg 250
34219323 A zpg B 44.13 250
34219323 A aqg S 44.18 100
34219323 A bqg S 44.19 200
34219330 A cqg B 44.09 100
34219331 R tpg 100
34219332 A dqg S 44.17 100
34219332 R fpg 100
34219332 R fog 200
34219332 R aqg 100
34219332 R cqg 100
34219333 A eqg S 44.18 100
34219333 R dqg 100
34219333 A fqg S 44.19 200
34219334 A gqg B 44.13 100
34219334 R fqg 200
34219334 R eqg 100
34219335 A hqg S 44.18 100
34219335 R gqg 100
34219340 R xpg 100
34219343 R qpg 100
34219348 A iqg S 44.20 100
34219353 A jqg S 44.18 100
34219363 A kqg B 44.09 100
34219370 A lqg S 44.25 100
34219371 R zpg 250
34219371 R bqg 200
34219372 R hqg 100
34219372 A mqg S 44.18 200
34219372 A nqg S 44.18 100
34219373 A oqg B 44.12 250
34219374 R nqg 100
34219374 A pqg S 44.18 100
34219381 R mqg 200
34219381 R pqg 100
34219381 A qqg S 44.19 200
34219381 R oqg 250
34219381 A rqg S 44.18 100
34219382 A sqg B 44.13 250
34219388 R qqg 200
34219389 R rqg 100
34219389 A tqg S 44.18 200
34219390 A uqg S 44.18 100
34219391 R tqg 200
34219392 A vqg S 44.19 200
34219392 R uqg 100
34219392 A wqg S 44.18 100
34219398 A xqg B 44.15 100
34219402 A yqg S 44.25 100
34219403 R lqg 100
34219403 A zqg B 44.09 100
34219404 R kqg 100
34219410 R vqg 200
34219411 R yqg 100
34219411 R wqg 100
34219412 R npg 250
34219412 A arg S 44.18 100
34219412 R ipg 100
34219412 R jpg 100
34219412 A brg B 44.15 100
34219413 A crg B 44.15 100
34219413 A drg S 44.19 200
34219414 A erg S 44.19 250
34219416 A frg B 44.14 100
34219436 A grg B 44.09 100
34219436 R zqg 100
34219442 A hrg S 44.24 100
34219442 R hrg 100
34219466 A irg S 44.18 100
34219468 A jrg B 44.09 100
34219468 R grg 100
34219469 R arg 100
34219470 R drg 200
34219470 A krg S 44.18 100
34219470 R irg 100
34219470 A lrg S 44.19 200
34219470 A mrg S 44.18 100
34219471 R krg 100
34219471 A nrg S 44.19 100
34219472 R lrg 200
34219473 A org S 44.25 100
34219478 R nrg 100
34219478 R mrg 100
34219479 A prg S 44.18 100
34219479 A qrg S 44.18 100
34219479 A rrg S 44.19 200
34219489 R qrg 100
34219489 R rrg 200
34219490 A srg S 44.18 100
34219490 R prg 100
34219491 A trg S 44.18 100
34219491 A urg S 44.19 200
34219491 R erg 250
34219492 A vrg S 44.18 250
34219496 R xqg 100
34219498 R srg 100
34219499 A wrg S 44.18 100
34219502 A xrg B 44.09 100
34219502 R jrg 100
34219512 R xrg 100
34219513 A yrg B 44.16 100
34219514 R crg 100
34219514 A zrg B 44.16 100
34219515 R brg 100
34219515 A asg B 44.16 100
34219519 R wrg 100
34219520 A bsg S 44.18 100
34219521 R vrg 250
34219522 R bsg 100
34219522 A csg S 44.18 100
34219524 A dsg S 44.19 250
34219525 R yrg 100
34219536 A esg B 44.16 100
34219536 R zrg 100
34219537 A fsg B 44.16 100
34219537 R asg 100
34219537 A gsg B 44.16 100
34219543 A hsg B 44.09 100
34219552 A isg B 44.09 100
34219552 R hsg 100
34219560 R dsg 250
34219561 A jsg S 44.18 250
34219562 R sqg 250
34219562 R jsg 250
34219565 A ksg B 44.12 250
34219565 R uog 100
34219565 A lsg S 44.19 250
34219591 A msg B 44.09 100
34219591 R isg 100
34219608 R csg 100
34219608 A nsg S 44.19 100
34219621 A osg B 44.10 100
34219621 R msg 100
34219703 R urg 200
34219703 R trg 100
34219704 A psg S 44.19 100
34219709 R frg 100
34219709 R iqg 100
34219722 R apg 100
34219724 A qsg S 44.19 200
34219724 R nsg 100
34219725 A rsg S 44.19 100
34219725 R qsg 200
34219732 R org 100
34219732 R rsg 100
34219734 A ssg S 44.19 100
34219741 A tsg S 44.19 200
34219744 R esg 100
34219745 R tsg 200
34219745 A usg S 44.18 100
34219752 A vsg B 44.10 100
34219753 R osg 100
34219754 A wsg B 44.16 100
34219755 R fsg 100
34219755 A xsg B 44.16 100
34219755 R gsg 100
34219756 A ysg B 44.16 100
34219758 A zsg S 44.19 200
34219762 A atg S 44.25 100
34219783 A btg B 44.10 100
34219784 R vsg 100
34219810 R ksg 250
34219811 A ctg B 44.13 250
34219950 R psg 100
34219950 R zsg 200
34219950 A dtg S 44.18 200
34219951 A etg S 44.18 100
34219951 R ssg 100
34219951 R lsg 250
34219952 A ftg S 44.18 100
34219952 A gtg S 44.18 250
34219957 R wsg 100
34219957 R ysg 100
34219958 R ftg 100
34219958 A htg B 44.13 100
34219958 A itg S 44.18 100
34219964 R jqg 100
34219975 A jtg S 44.18 100
34219976 R itg 100
34219976 A ktg S 44.17 100
34219981 R btg 100
34219984 R xsg 100
34219985 R etg 100
34219985 A ltg B 44.13 44
34219986 A mtg S 44.17 100
34219987 R ktg 100
34219987 A ntg B 44.13 100
34219987 A otg B 44.11 200
34219987 A ptg S 44.17 100
34219988 R htg 100
34219988 A qtg B 44.13 100
34219988 A rtg B 44.14 100
34219988 R mtg 100
34219989 R ltg 44
34219989 A stg B 44.14 100
34219989 A ttg S 44.17 56
34219992 A utg S 44.25 100
34219992 R atg 100
34219996 R qtg 100
34219996 R qog 200
34219997 A vtg B 44.14 200
34220004 A wtg B 44.14 100
34220005 R stg 100
34220005 R rtg 100
34220005 A xtg B 44.14 100
34220006 A ytg B 44.14 100
34220007 R ntg 100
34220011 A ztg B 44.07 100
34220012 R vtg 200
34220012 A aug B 44.13 200
34220016 R wtg 100
34220022 A bug S 44.17 100
34220023 R gtg 250
34220024 A cug S 44.18 250
34220024 R ptg 100
34220025 A dug S 44.17 100
34220025 R dtg 200
34220026 R ttg 56
34220026 A eug S 44.18 200
34220026 A fug S 44.17 56
34220032 A gug B 44.07 100
34220033 R ztg 100
34220034 A hug S 44.25 100
34220034 R utg 100
34220038 R cug 250
34220040 A iug S 44.18 250
34220063 A jug B 44.07 100
34220063 R gug 100
34220065 A kug S 44.24 100
34220065 R hug 100
34220094 A lug B 44.07 100
34220094 R jug 100
34220134 A mug B 44.07 100
34220134 R lug 100
34220162 R ctg 250
34220163 R iug 250
34220163 A nug B 44.14 250
34220163 A oug S 44.18 250
34220164 R aug 200
34220164 A pug B 44.14 200
34220165 A qug B 44.07 100
34220165 R mug 100
34220181 A rug S 44.17 100
34220187 R oug 250
34220190 A sug S 44.18 250
34220192 R nug 250
34220194 A tug S 44.24 100
34220194 R kug 100
34220195 A uug B 44.13 250
34220197 A vug B 44.07 100
34220197 R qug 100
34220228 A wug B 44.07 100
34220228 R vug 100
34220254 A xug B 44.14 100
34220255 R ytg 100
34220255 A yug B 44.14 100
34220256 R xtg 100
34220256 R dug 100
34220256 A zug B 44.14 100
34220257 A avg S 44.17 100
34220258 A bvg B 44.08 100
34220259 R wug 100
34220262 R xug 100
34220265 R otg 200
34220290 A cvg B 44.08 100
34220290 R bvg 100
34220290 R tug 100
34220295 R rug 100
34220321 A dvg S 44.24 100
34220348 R sug 250
34220349 A evg S 44.18 250
34220424 A fvg S 44.16 500
34220425 R pug 200
34220425 R avg 100
34220425 A gvg B 44.13 200
34220425 A hvg S 44.17 100
34220426 R fug 56
34220426 A ivg S 44.16 56
34220453 A jvg B 44.11 600
34220458 R evg 250
34220460 A kvg S 44.18 250
34220466 R kvg 250
34220466 A lvg S 44.18 250
34220468 A mvg S 44.24 100
34220469 R dvg 100
34220485 A nvg B 43.56 25
34220493 R zug 100
34220493 A ovg B 44.13 100
34220496 A pvg B 44.12 100
34220520 R uug 250
34220522 R cvg 100
34220522 A qvg B 44.12 250
34220534 A rvg S 44.24 100
34220534 R mvg 100
34220549 R qvg 250
34220549 A svg B 44.13 250
34220552 A tvg B 44.07 100
34220570 A uvg S 44.24 100
34220570 R rvg 100
34220777 R usg 100
34221230 R lvg 250
34221230 A vvg S 44.17 250
34221231 R eug 200
34221232 A wvg S 44.17 200
34221261 A xvg S 44.24 100
34221261 R uvg 100
34221852 A yvg S 44.16 200
34221890 A zvg S 44.24 100
34221890 R xvg 100
34222291 R ivg 56
34222401 A awg S 44.16 56
34222446 R svg 250
34222448 A bwg B 44.12 250
34222469 R awg 56
34222499 A cwg S 44.17 100
34222500 R hvg 100
34222500 A dwg S 44.17 100
34222502 R cwg 100
34222502 A ewg S 44.17 100
34222503 R dwg 100
34222503 A fwg S 44.16 100
34222504 R ewg 100
34222504 A gwg S 44.16 100
34222515 R bwg 250
34222516 A hwg B 44.13 250
34222535 A iwg S 44.23 100
34222535 R zvg 100
34223322 A jwg S 44.23 100
34223322 R iwg 100
34223377 A kwg S 44.16 100
34223688 R bug 100
34225505 R hwg 250
34225508 A lwg B 44.12 250
34225579 R yug 100
34225579 R fwg 100
34225579 R gvg 200
34225579 A mwg B 44.13 68
34225579 R vvg 250
34225579 A nwg B 44.13 200
34225580 R gwg 100
34225580 A owg S 44.17 250
34225580 A pwg S 44.16 100
34225580 A qwg S 44.16 100
34225581 R wvg 200
34225581 R nwg 200
34225581 A rwg S 44.16 200
34225583 A swg B 44.11 200
34225584 A twg B 44.13 100
34225585 A uwg S 44.16 100
34225586 R mwg 68
34225586 A vwg B 44.14 68
34225587 A wwg B 44.13 100
34225587 R jtg 100
34225588 R swg 200
34225588 A xwg B 44.13 200
34225592 R lwg 250
34225592 R ovg 100
34225592 A ywg B 44.13 100
34225594 R xwg 200
34225594 R rwg 200
34225594 A zwg S 44.16 200
34225595 A axg B 44.12 250
34225596 R pvg 100
34225597 A bxg S 44.16 100
34225598 R pwg 100
34225599 A cxg S 44.16 100
34225599 R qwg 100
34225599 A dxg S 44.16 100
34225602 A exg B 44.12 200
34225609 R wwg 100
34225609 R bxg 100
34225610 A fxg S 44.22 100
34225610 R jwg 100
34225613 A gxg S 44.16 100
34225614 R cxg 100
34225615 A hxg S 44.15 100
34225616 R dxg 100
34225616 A ixg S 44.16 100
34225616 A jxg S 44.15 100
34225617 R axg 250
34225619 A kxg B 44.11 250
34225622 R gxg 100
34225623 R tvg 100
34225630 A lxg S 44.15 100
34225631 R jxg 100
34225631 A mxg S 44.15 100
34225633 R hxg 100
34225633 R vwg 68
34225633 A nxg B 44.13 68
34225634 A oxg S 44.15 100
34225636 R owg 250
34225636 A pxg S 44.16 250
34225639 A qxg S 44.15 100
34225649 R exg 200
34225650 A rxg B 44.11 200
34225651 R kxg 250
34225651 R twg 100
34225653 A sxg B 44.06 100
34225653 A txg B 44.11 250
34225655 A uxg B 44.11 100
34225660 R ywg 100
34225660 A vxg B 44.12 100
34225664 A wxg B 44.06 100
34225664 R sxg 100
34225665 R uxg 100
34225671 R txg 250
34225673 A xxg S 44.15 100
34225673 A yxg B 44.11 250
34225675 A zxg B 44.10 100
34225679 R wxg 100
34225680 R pxg 250
34225680 A ayg S 44.15 250
34225681 R ayg 250
34225683 A byg S 44.16 250
34225692 A cyg S 44.22 100
34225692 R fxg 100
34225710 A dyg B 44.05 100
34226000 R yxg 250
34226001 A eyg B 44.11 250
34226009 R cyg 100
34226019 A fyg B 44.05 100
34226019 R dyg 100
34226040 A gyg S 44.22 100
34226049 A hyg B 44.06 100
34226049 R fyg 100
34226076 R byg 250
34226077 A iyg S 44.15 250
34226320 A jyg S 44.22 100
34226320 R gyg 100
34226351 R eyg 250
34226353 R zwg 200
34226353 A kyg S 44.15 200
34226353 A lyg B 44.11 250
34226723 R kwg 100
34226966 A myg S 44.14 400
34226968 A nyg S 44.14 100
34226969 A oyg S 44.14 100
34226990 R nyg 100
34226991 R zxg 100
34227017 R jyg 100
34227046 A pyg S 44.22 100
34227262 R uwg 100
34227751 A qyg B 42.66 3
34228073 A ryg B 43.63 400
34228170 R iyg 250
34228173 A syg S 44.16 250
34228342 R lyg 250
34228342 A tyg B 44.12 250
34228368 R tyg 250
34228368 A uyg B 44.13 250
34228369 R nxg 68
34228370 A vyg B 44.13 68
34228370 R kyg 200
34228411 A wyg B 44.06 100
34228412 R hyg 100
34228442 A xyg B 44.06 100
34228442 R wyg 100
34228613 R myg 100
34228645 A yyg S 44.14 100
34228748 R myg 100
34229008 R ixg 100
34229159 R myg 20
34229175 R myg 180
34229514 A zyg B 44.13 100
34229515 A azg B 44.13 100
34229547 A bzg S 44.14 180
34229547 R mxg 100
34229548 A czg S 44.14 100
34229548 R vxg 100
34229549 A dzg B 44.11 100
34229612 A ezg S 44.22 100
34229612 R pyg 100
34229884 R azg 100
34229886 R zyg 100
34229969 A fzg B 44.13 100
34229972 A gzg B 44.13 100
34229974 R gzg 100
34230054 A hzg B 44.13 100
34230058 R bzg 180
34230059 R czg 100
34230059 R dzg 100
34230059 A izg S 44.15 100
34230060 A jzg B 44.13 100
34230060 A kzg S 44.14 100
34230060 R hzg 100
34230062 R fzg 100
34230068 R qxg 100
34230106 R kzg 100
34230126 A lzg S 46.25 33
34230129 R ezg 100
34230161 A mzg S 44.22 100
34230293 A nzg B 44.13 100
34230296 A ozg B 44.13 100
34230348 A pzg S 44.65 400
34230352 R ozg 100
34230354 R nzg 100
34230382 R syg 250
34230385 A qzg S 44.17 250
34230486 R yyg 100
34230487 A rzg S 44.16 200
34230487 A szg S 44.14 100
34230487 R szg 100
34230488 A tzg S 44.15 100
34230489 A uzg S 44.14 100
34230808 R uzg 100
34230913 R qzg 250
34230913 A vzg S 44.16 250
34230933 R vzg 250
34230935 A wzg S 44.17 250
34231032 R wzg 250
34231032 A xzg S 44.16 250
34231134 R xzg 250
34231137 A yzg S 44.17 250
34231158 R xxg 100
34231279 R xyg 100
34231308 A zzg B 44.06 100
34231485 R vyg 68
34231485 R uyg 139
34231488 R oxg 100
34231489 A aah S 44.15 100
34231490 R izg 100
34231491 A bah S 44.15 100
34231491 R aah 100
34231492 A cah S 44.15 100
34231493 R bah 100
34231493 A dah S 44.15 100
34231495 R uyg 111
34231495 R yzg 250
34231495 A eah S 44.17 100
34231495 A fah S 44.16 250
34231496 R jzg 100
34231496 R dah 100
34231496 A gah B 44.11 100
34231496 A hah S 44.14 100
34231497 R cah 100
34231497 A iah S 44.14 100
34231498 R rxg 200
34231499 A jah B 44.11 200
34231510 R iah 100
34231510 A kah S 44.15 100
34231518 R kah 100
34231518 A lah S 44.14 100
34231520 A mah S 44.22 100
34231520 R fah 250
34231520 R mzg 100
34231520 R zzg 100
34231521 A nah S 44.15 250
34231551 A oah B 44.05 100
34231570 R lah 100
34231570 A pah S 44.15 100
34231570 R rzg 200
34231571 A qah S 44.15 200
34231590 R pah 100
34231590 R nah 250
34231591 A rah S 44.15 100
34231592 R rah 100
34231592 A sah S 44.15 100
34231594 A tah S 44.16 250
34231600 R tah 250
34231600 A uah S 44.15 250
34231601 R sah 100
34231601 R gah 100
34231601 A vah B 44.13 100
34231601 A wah B 44.05 100
34231602 R oah 100
34231602 A xah S 44.15 100
34231602 A yah S 44.15 100
34231602 R hah 100
34231603 R xah 100
34231604 A zah S 44.15 100
34231610 R uah 250
34231613 A abh S 44.16 250
34231634 A bbh B 44.05 100
34231634 R wah 100
34231877 R tfg 300
34232035 A cbh S 44.14 100
34232036 R vah 100
34232036 R yah 100
34232036 A dbh B 44.11 100
34232037 A ebh S 44.14 100
34232038 R zah 100
34232038 A fbh S 44.14 100
34232038 R lxg 100
34232040 R eah 100
34232040 A gbh B 44.10 100
34232048 R jah 200
34232050 R abh 250
34232051 A hbh S 44.15 250
34232079 A ibh S 44.21 100
34232079 R mah 100
34232156 A jbh S 44.14 300
34232157 R fbh 100
34232158 A kbh S 44.14 100
34232159 R ebh 100
34232159 A lbh S 44.14 100
34232173 R hbh 250
34232174 A mbh S 44.15 250
34232199 A nbh S 44.21 100
34232200 R ibh 100
34232231 A obh S 44.21 100
34232231 R nbh 100
34232261 A pbh S 44.21 100
34232262 R obh 100
34232270 R tzg 100
34232898 A qbh B 44.11 100
34232898 R kbh 100
34232899 R qah 200
34232899 A rbh S 44.14 100
34232899 A sbh S 44.15 200
34232919 R gbh 100
34232928 R bbh 100
34232959 A tbh B 44.05 100
34233903 R mbh 250
34233906 A ubh S 44.17 250
34233957 A vbh S 44.13 200
34233958 R lbh 100
34233958 R qbh 100
34233958 R rbh 100
34233959 R dbh 100
34233959 A wbh B 44.11 100
34233959 A xbh S 44.14 100
34233959 A ybh S 44.13 100
34233959 A zbh B 44.09 200
34233959 A ach B 44.09 100
34233964 R cbh 100
34233989 R ubh 250
34233990 A bch S 44.17 250
34233999 R tbh 100
34234000 A cch S 44.21 100
34234000 R pbh 100
34234026 R bch 250
34234029 A dch B 44.04 100
34234029 A ech S 44.17 250
34234031 R ofe 100
34234032 R xbh 100
34234032 R wbh 100
34234032 A fch B 44.09 100
34234034 A gch S 44.13 100
34234034 R ach 100
34234035 A hch B 44.09 100
34234036 R fch 100
34234036 A ich B 44.09 100
34234036 A jch B 44.09 100
34234037 R hch 100
34234037 A kch B 44.10 100
34234040 R dch 100
34234058 A lch S 44.20 100
34234058 R cch 100
34234071 A mch B 44.04 100
34234078 R mch 100
34234083 R vbh 100
34234084 R ich 100
34234084 A nch B 44.10 100
34234084 R gch 100
34234084 A och S 44.14 100
34234084 R kch 100
34234085 A pch B 44.10 100
34234085 R nch 100
34234085 A qch B 44.10 100
34234087 R pch 100
34234087 A rch B 44.10 100
34234088 R qch 100
34234088 A sch B 44.10 100
34234088 A tch S 44.20 100
34234089 R rch 100
34234089 R lch 100
34234089 A uch B 44.10 100
34234090 A vch B 44.10 100
34234090 R sch 100
34234091 R uch 100
34234091 A wch B 44.10 100
34234092 R vch 100
34234092 A xch B 44.11 100
34234093 R wch 100
34234093 A ych B 44.11 100
34234094 R xch 100
34234094 A zch B 44.11 100
34234095 R ych 100
34234095 A adh B 44.11 100
34234096 R zch 100
34234096 A bdh B 44.11 100
34234113 A cdh B 44.04 100
34234689 R vbh 100
34234690 R adh 100
34234690 R bdh 100
34234690 A ddh B 44.11 100
34234691 A edh B 44.11 100
34234698 R ybh 100
34234698 A fdh S 44.14 100
34234700 R ech 250
34234702 A gdh S 44.18 250
34234709 R edh 100
34234709 A hdh B 44.11 100
34234710 R och 100
34234710 A idh S 44.14 100
34234710 R ddh 100
34234711 A jdh B 44.12 100
34234711 R fdh 100
34234712 A kdh S 44.14 100
34234729 A ldh B 44.04 100
34234729 R cdh 100
34234729 R tch 100
34234730 R hdh 100
34234730 A mdh B 44.11 100
34234745 A ndh S 44.13 1000
34234746 R mdh 100
34234746 R idh 100
34234746 R jdh 100
34234746 R kdh 100
34234746 A odh B 44.09 100
34234746 A pdh B 44.09 100
34234747 A qdh S 44.13 100
34234747 A rdh S 44.13 100
34234747 R zbh 200
34234748 A sdh B 44.10 200
34234749 R odh 100
34234749 A tdh B 44.10 100
34234749 R pdh 100
34234749 A udh B 44.10 100
34234750 R sdh 200
34234750 A vdh B 44.10 200
34234751 R tdh 100
34234751 A wdh B 44.10 100
34234752 R udh 100
34234752 A xdh B 44.10 100
34234753 R vdh 200
34234753 A ydh B 44.10 200
34234754 R wdh 100
34234754 A zdh B 44.10 100
34234754 R gdh 250
34234754 R xdh 100
34234755 A aeh B 44.10 100
34234755 A beh S 44.17 250
34234760 R beh 250
34234761 A ceh S 44.21 100
34234762 A deh S 44.17 250
34234763 R deh 250
34234764 A eeh S 44.17 250
34234766 R eeh 250
34234768 A feh S 44.17 250
34234789 R ldh 100
34234789 A geh S 44.21 100
34234790 R ceh 100
34234819 A heh B 44.04 100
34234821 A ieh S 44.20 100
34234821 R geh 100
34234851 A jeh S 44.20 100
34234852 R ieh 100
34234943 R ndh 100
34235027 A keh S 44.14 100
34235334 A leh S 44.20 100
34235334 R jeh 100
34235382 A meh S 44.15 200
34235400 R feh 250
34235406 A neh S 44.15 250
34235480 R neh 250
34235483 A oeh S 44.16 250
34235788 R jvg 600
34235794 A peh B 44.11 400
34235796 A qeh B 44.10 100
34235797 R aeh 100
34235797 A reh B 44.11 100
34235798 R zdh 100
34235798 A seh B 44.10 100
34235799 R peh 400
34236071 R keh 100
34236154 A teh S 44.14 100
34236298 R oeh 250
34236825 A ueh S 44.16 250
34236918 R ndh 900
34236922 A veh S 44.13 100
34236923 A weh S 44.13 200
34236924 R rdh 100
34236924 A xeh S 44.13 100
34236925 R weh 200
34236929 R ueh 250
34236931 A yeh S 44.17 250
34237843 R teh 100
34238113 R yeh 250
34238113 A zeh S 44.16 250
34238130 A afh B 44.11 300
34238840 A bfh S 44.13 100
34238845 A cfh B 44.12 200
34238846 R seh 100
34238846 R xeh 100
34238846 R qdh 100
34238846 A dfh S 44.14 100
34238846 A efh B 44.11 100
34238846 A ffh S 44.13 100
34238848 R bfh 100
34238849 R reh 100
34238849 A gfh B 44.11 100
34238850 A hfh S 44.13 100
34238850 R jch 100
34238860 R zeh 250
34238860 A ifh S 44.15 250
34238866 R cfh 100
34238890 A jfh B 44.04 100
34238890 R heh 100
34238914 R ifh 250
34238916 A kfh S 44.16 250
34238963 A lfh B 44.13 100
34238964 R ffh 100
34238964 R efh 100
34238964 A mfh B 44.11 100
34238964 A nfh S 44.14 100
34238965 R gfh 100
34238965 A ofh B 44.11 100
34238966 R dfh 100
34238966 A pfh S 44.14 100
34238967 R mfh 100
34238967 A qfh B 44.11 100
34238968 R ofh 100
34238968 A rfh B 44.12 100
34238969 R ydh 200
34238970 A sfh B 44.11 200
34238980 R nfh 100
34238980 A tfh S 44.14 100
34238990 R kfh 250
34238990 A ufh S 44.15 250
34239010 A vfh B 44.05 100
34239011 R jfh 100
34239019 R pfh 100
34239020 A wfh S 44.14 100
34239040 A xfh B 44.05 100
34239040 R vfh 100
34239072 A yfh B 44.05 100
34239073 R xfh 100
34239143 R hfh 100
34239145 R sbh 200
34239202 R meh 200
34239206 R veh 100
34239206 R qfh 100
34239207 A zfh B 44.12 100
34239207 R tfh 100
34239207 A agh S 44.14 100
34239208 A bgh S 44.15 200
34239208 A cgh B 44.12 100
34239208 R rfh 100
34239230 R leh 100
34239261 A dgh S 44.21 100
34239262 A egh S 44.14 100
34239334 R egh 100
34239483 A fgh S 44.14 100
34239737 R fgh 100
34239799 R lfh 100
34239799 R cfh 100
34239799 A ggh S 44.12 800
34239800 R sfh 200
34239800 R zfh 100
34239800 A hgh B 44.11 100
34239800 R agh 100
34239800 R wfh 100
34239800 R cgh 100
34239800 A igh B 44.11 100
34239801 A jgh S 44.13 100
34239801 A kgh S 44.13 100
34239802 R hgh 100
34239802 A lgh B 44.10 100
34239804 A mgh B 44.10 100
34239805 R qeh 100
34239806 A ngh B 44.09 200
34239810 R ufh 250
34239810 A ogh S 44.15 250
34239811 R bgh 200
34239812 A pgh S 44.15 200
34239812 A qgh B 44.11 100
34239814 A rgh B 44.11 100
34239823 R igh 100
34239823 A sgh B 44.10 100
34239826 R mgh 100
34239827 R qgh 100
34239837 R ggh 800
34239838 R kgh 100
34239838 R lgh 100
34239838 A tgh S 44.14 100
34239838 A ugh B 44.11 100
34239839 A vgh S 44.13 100
34239842 A wgh S 44.21 100
34239842 R dgh 100
34239842 R yfh 100
34239846 R ogh 250
34239846 A xgh S 44.14 250
34239852 R sgh 100
34239852 R jgh 100
34239853 A ygh B 44.11 100
34239853 R rgh 100
34239853 R tgh 100
34239853 A zgh S 44.14 100
34239853 A ahh S 44.14 100
34239854 R zgh 100
34239855 A bhh S 44.14 100
34239858 R bhh 100
34239859 A chh S 44.13 100
34239861 R vgh 100
34239864 A dhh S 44.13 100
34239870 R chh 100
34239871 A ehh S 44.14 100
34239873 A fhh B 44.04 100
34239875 R xgh 250
34239881 A ghh S 44.15 250
34239891 R ehh 100
34239891 R ugh 100
34239891 R ahh 100
34239891 A hhh B 44.09 100
34239891 A ihh B 44.09 100
34239891 A jhh S 44.20 100
34239891 A khh S 44.13 100
34239891 R wgh 100
34239892 A lhh B 44.04 100
34239892 A mhh S 44.13 100
34239892 R ygh 100
34239892 R ngh 200
34239892 R fhh 100
34239892 A nhh B 44.09 200
34239893 R ihh 100
34239894 R dhh 100
34239894 A ohh B 44.09 100
34239894 A phh B 44.09 100
34239894 R hhh 100
34239895 R nhh 200
34239895 A qhh S 44.13 100
34239896 A rhh B 44.10 200
34239896 R pgh 200
34239897 A shh S 44.13 200
34239897 R phh 100
34239898 R ohh 100
34239898 A thh B 44.10 100
34239898 A uhh B 44.10 100
34239899 A vhh S 44.13 100
34239899 R jhh 100
34239899 R rhh 200
34239899 A whh B 44.10 200
34239900 R mhh 100
34239900 R khh 100
34239900 A xhh S 44.13 100
34239900 R uhh 100
34239900 R shh 200
34239901 A yhh B 44.10 100
34239901 R thh 100
34239901 A zhh S 44.13 100
34239901 A aih B 44.10 100
34239901 R qhh 100
34239901 A bih S 44.14 200
34239901 R ghh 250
34239902 A cih B 44.09 200
34239902 R whh 200
34239902 A dih S 44.14 250
34239903 R bih 200
34239903 A eih S 44.13 200
34239903 A fih S 44.13 100
34239912 R vhh 100
34239919 A gih S 44.13 100
34239920 R lhh 100
34239921 R fih 100
34239922 R zhh 100
34239922 A hih S 44.13 100
34239923 A iih S 44.13 100
34239923 R xhh 100
34239924 A jih S 44.13 100
34239924 R iih 100
34239925 A kih S 44.12 200
34239926 R gih 100
34239927 R hih 100
34239927 A lih S 44.12 100
34239928 A mih S 44.13 100
34239928 R mih 100
34239941 R kih 200
34239942 R jih 100
34239942 A nih S 44.13 100
34239943 A oih S 44.19 100
34239950 A pih B 44.03 100
34239950 R eih 200
34239950 R lih 100
34239950 A qih B 44.10 200
34239951 A rih S 44.14 200
34239951 A sih S 44.13 100
34239951 R cih 200
34239951 R aih 100
34239951 R yhh 100
34239951 A tih B 44.11 100
34239951 A uih B 44.10 100
34239955 A vih S 44.15 100
34239962 A wih B 44.11 100
34239964 A xih S 44.13 100
34239972 R vih 100
34239973 A yih S 44.19 100
34239973 A zih S 44.12 200
34239973 R oih 100
34239974 R qih 200
34239974 R tih 100
34239974 R rih 200
34239974 A ajh B 44.10 100
34239975 R xih 100
34239975 A bjh B 44.09 200
34239977 A cjh S 44.13 200
34239979 R uih 100
34239979 A djh B 44.10 100
34239980 R dih 250
34239981 A ejh S 44.14 250
34239981 R ajh 100
34239981 A fjh B 44.10 100
34239982 R pih 100
34239982 R yih 100
34239987 R ejh 250
34239989 R djh 100
34239990 A gjh B 44.09 100
34239990 A hjh S 44.14 250
34239992 R hjh 250
34239993 A ijh S 44.14 250
34239995 R zih 200
34239996 R gjh 100
34239996 R cjh 200
34239996 R fjh 100
34239997 A jjh B 44.11 100
34239997 A kjh B 44.11 100
34239997 A ljh S 44.16 200
34239998 R ijh 250
34240002 A mjh S 44.14 250
34240003 R jjh 100
34240003 A njh B 44.11 100
34240011 R mjh 250
34240012 A ojh S 44.13 100
34240013 A pjh B 44.04 100
34240014 A qjh S 44.20 100
34240015 A rjh S 44.14 250
34240015 R sih 100
34240016 A sjh S 44.13 100
34240016 R ljh 200
34240017 A tjh S 44.14 200
34240022 A ujh S 44.20 100
34240023 R qjh 100
34240027 R rjh 250
34240027 A vjh S 44.14 250
34240033 R wih 100
34240038 A wjh S 44.13 100
34240040 R wjh 100
34240040 R njh 100
34240040 R sjh 100
34240041 A xjh B 44.11 100
34240041 R nih 100
34240041 A yjh S 44.13 100
34240041 R kjh 100
34240041 A zjh S 44.13 100
34240041 A akh B 44.09 100
34240042 R xjh 100
34240042 A bkh B 44.09 100
34240042 A ckh S 44.13 100
34240043 R bjh 200
34240043 A dkh B 44.09 200
34240043 R tjh 200
34240044 A ekh S 44.13 200
34240044 R ckh 100
34240044 R bkh 100
34240044 A fkh B 44.09 100
34240045 R akh 100
34240045 A gkh B 44.09 100
34240045 R ekh 200
34240046 R dkh 200
34240046 A hkh B 44.10 200
34240047 R gkh 100
34240047 A ikh B 44.10 100
34240048 R fkh 100
34240048 A jkh B 44.10 100
34240048 R vjh 250
34240049 R hkh 200
34240049 A kkh B 44.10 200
34240050 R jkh 100
34240050 A lkh B 44.10 100
34240051 R ikh 100
34240051 A mkh B 44.10 100
34240053 A nkh S 44.20 100
34240054 R ujh 100
34240054 A okh S 44.14 250
34240055 A pkh S 44.14 200
34240059 R kkh 200
34240060 A qkh B 44.10 200
34240060 R lkh 100
34240061 A rkh B 44.10 100
34240061 R mkh 100
34240061 A skh B 44.10 100
34240069 R pjh 100
34240080 R okh 250
34240081 A tkh S 44.14 250
34240084 A ukh S 44.13 100
34240085 R qkh 200
34240085 A vkh B 44.09 200
34240094 A wkh S 44.12 200
34240095 R pkh 200
34240095 A xkh S 44.13 200
34240096 R ukh 100
34240099 A ykh B 44.03 100
34240151 R skh 100
34240151 A zkh B 44.09 100
34240152 R yjh 100
34240152 A alh S 44.13 100
34240184 A blh S 44.19 100
34240184 R nkh 100
34240184 R ykh 100
34240215 A clh S 44.19 100
34240216 R blh 100
34240217 A dlh B 44.03 100
34240231 A elh B 44.03 100
34240232 R dlh 100
34240588 R afh 63
34240589 R zjh 100
34240589 A flh S 44.12 100
34240589 R tkh 250
34240590 A glh S 44.13 250
34240591 R wkh 200
34240592 R flh 100
34240592 R alh 100
34240592 A hlh S 44.13 100
34240592 A ilh S 44.13 100
34240593 A jlh S 44.12 100
34240593 R zkh 100
34240593 A klh B 44.10 100
34240594 R rkh 100
34240595 A llh B 44.10 100
34240595 R jlh 100
34240595 A mlh S 44.13 100
34240597 R mlh 100
34240597 A nlh S 44.12 100
34240599 R nlh 100
34240607 R afh 39
34240644 R afh 198
34240644 R glh 250
34240644 R klh 100
34240644 R hlh 100
34240644 R xkh 200
34240644 A olh S 44.13 100
34240645 A plh S 44.14 200
34240645 A qlh S 44.13 100
34240646 A rlh B 44.10 100
34240646 A slh B 44.09 100
34240646 R llh 100
34240646 R ilh 100
34240647 A tlh S 44.13 200
34240647 R plh 200
34240647 A ulh S 44.13 100
